2018-03-22 08:26:09,775 INFO: Medium startup [in /home/emmisteel/Documents/flask_projects/medium/app/__init__.py:49]
2018-03-22 08:26:34,665 ERROR: Exception on /edit_profile [POST] [in /home/emmisteel/anaconda3/envs/my_venv_3_64/lib/python3.6/site-packages/flask/app.py:1560]
Traceback (most recent call last):
  File "/home/emmisteel/anaconda3/envs/my_venv_3_64/lib/python3.6/site-packages/sqlalchemy/engine/base.py", line 1182, in _execute_context
    context)
  File "/home/emmisteel/anaconda3/envs/my_venv_3_64/lib/python3.6/site-packages/sqlalchemy/engine/default.py", line 470, in do_execute
    cursor.execute(statement, parameters)
sqlite3.IntegrityError: UNIQUE constraint failed: user.username

The above exception was the direct cause of the following exception:

Traceback (most recent call last):
  File "/home/emmisteel/anaconda3/envs/my_venv_3_64/lib/python3.6/site-packages/flask/app.py", line 1982, in wsgi_app
    response = self.full_dispatch_request()
  File "/home/emmisteel/anaconda3/envs/my_venv_3_64/lib/python3.6/site-packages/flask/app.py", line 1614, in full_dispatch_request
    rv = self.handle_user_exception(e)
  File "/home/emmisteel/anaconda3/envs/my_venv_3_64/lib/python3.6/site-packages/flask/app.py", line 1517, in handle_user_exception
    reraise(exc_type, exc_value, tb)
  File "/home/emmisteel/anaconda3/envs/my_venv_3_64/lib/python3.6/site-packages/flask/_compat.py", line 33, in reraise
    raise value
  File "/home/emmisteel/anaconda3/envs/my_venv_3_64/lib/python3.6/site-packages/flask/app.py", line 1612, in full_dispatch_request
    rv = self.dispatch_request()
  File "/home/emmisteel/anaconda3/envs/my_venv_3_64/lib/python3.6/site-packages/flask/app.py", line 1598, in dispatch_request
    return self.view_functions[rule.endpoint](**req.view_args)
  File "/home/emmisteel/anaconda3/envs/my_venv_3_64/lib/python3.6/site-packages/flask_login/utils.py", line 228, in decorated_view
    return func(*args, **kwargs)
  File "/home/emmisteel/Documents/flask_projects/medium/app/routes.py", line 86, in edit_profile
    db.session.commit()
  File "/home/emmisteel/anaconda3/envs/my_venv_3_64/lib/python3.6/site-packages/sqlalchemy/orm/scoping.py", line 157, in do
    return getattr(self.registry(), name)(*args, **kwargs)
  File "/home/emmisteel/anaconda3/envs/my_venv_3_64/lib/python3.6/site-packages/sqlalchemy/orm/session.py", line 906, in commit
    self.transaction.commit()
  File "/home/emmisteel/anaconda3/envs/my_venv_3_64/lib/python3.6/site-packages/sqlalchemy/orm/session.py", line 461, in commit
    self._prepare_impl()
  File "/home/emmisteel/anaconda3/envs/my_venv_3_64/lib/python3.6/site-packages/sqlalchemy/orm/session.py", line 441, in _prepare_impl
    self.session.flush()
  File "/home/emmisteel/anaconda3/envs/my_venv_3_64/lib/python3.6/site-packages/sqlalchemy/orm/session.py", line 2177, in flush
    self._flush(objects)
  File "/home/emmisteel/anaconda3/envs/my_venv_3_64/lib/python3.6/site-packages/sqlalchemy/orm/session.py", line 2297, in _flush
    transaction.rollback(_capture_exception=True)
  File "/home/emmisteel/anaconda3/envs/my_venv_3_64/lib/python3.6/site-packages/sqlalchemy/util/langhelpers.py", line 66, in __exit__
    compat.reraise(exc_type, exc_value, exc_tb)
  File "/home/emmisteel/anaconda3/envs/my_venv_3_64/lib/python3.6/site-packages/sqlalchemy/util/compat.py", line 187, in reraise
    raise value
  File "/home/emmisteel/anaconda3/envs/my_venv_3_64/lib/python3.6/site-packages/sqlalchemy/orm/session.py", line 2261, in _flush
    flush_context.execute()
  File "/home/emmisteel/anaconda3/envs/my_venv_3_64/lib/python3.6/site-packages/sqlalchemy/orm/unitofwork.py", line 389, in execute
    rec.execute(self)
  File "/home/emmisteel/anaconda3/envs/my_venv_3_64/lib/python3.6/site-packages/sqlalchemy/orm/unitofwork.py", line 548, in execute
    uow
  File "/home/emmisteel/anaconda3/envs/my_venv_3_64/lib/python3.6/site-packages/sqlalchemy/orm/persistence.py", line 177, in save_obj
    mapper, table, update)
  File "/home/emmisteel/anaconda3/envs/my_venv_3_64/lib/python3.6/site-packages/sqlalchemy/orm/persistence.py", line 737, in _emit_update_statements
    execute(statement, multiparams)
  File "/home/emmisteel/anaconda3/envs/my_venv_3_64/lib/python3.6/site-packages/sqlalchemy/engine/base.py", line 945, in execute
    return meth(self, multiparams, params)
  File "/home/emmisteel/anaconda3/envs/my_venv_3_64/lib/python3.6/site-packages/sqlalchemy/sql/elements.py", line 263, in _execute_on_connection
    return connection._execute_clauseelement(self, multiparams, params)
  File "/home/emmisteel/anaconda3/envs/my_venv_3_64/lib/python3.6/site-packages/sqlalchemy/engine/base.py", line 1053, in _execute_clauseelement
    compiled_sql, distilled_params
  File "/home/emmisteel/anaconda3/envs/my_venv_3_64/lib/python3.6/site-packages/sqlalchemy/engine/base.py", line 1189, in _execute_context
    context)
  File "/home/emmisteel/anaconda3/envs/my_venv_3_64/lib/python3.6/site-packages/sqlalchemy/engine/base.py", line 1402, in _handle_dbapi_exception
    exc_info
  File "/home/emmisteel/anaconda3/envs/my_venv_3_64/lib/python3.6/site-packages/sqlalchemy/util/compat.py", line 203, in raise_from_cause
    reraise(type(exception), exception, tb=exc_tb, cause=cause)
  File "/home/emmisteel/anaconda3/envs/my_venv_3_64/lib/python3.6/site-packages/sqlalchemy/util/compat.py", line 186, in reraise
    raise value.with_traceback(tb)
  File "/home/emmisteel/anaconda3/envs/my_venv_3_64/lib/python3.6/site-packages/sqlalchemy/engine/base.py", line 1182, in _execute_context
    context)
  File "/home/emmisteel/anaconda3/envs/my_venv_3_64/lib/python3.6/site-packages/sqlalchemy/engine/default.py", line 470, in do_execute
    cursor.execute(statement, parameters)
sqlalchemy.exc.IntegrityError: (sqlite3.IntegrityError) UNIQUE constraint failed: user.username [SQL: 'UPDATE user SET username=?, about_me=? WHERE user.id = ?'] [parameters: ('candy', 'I am a Software Engineer, interested in learning new technologies. Lover of one woman. Denise Karungi', 4)]
